<?xml version="1.0" encoding="UTF-8" ?>
<testsuites>
    <testsuite name="LuaUnit" id="00001" package="" hostname="localhost" tests="15" timestamp="2016-01-30T22:33:12" time="0.015" errors="4" failures="8">
        <properties>
            <property name="Lua Version" value="Lua 5.2"/>
            <property name="LuaUnit Version" value="3.2"/>
        </properties>
        <testcase classname="TestTiti" name="TestTiti.test1_withFailure" time="0.000">
            <failure type="example_with_luaunit.lua:102: expected: 2, actual: 1">
                <![CDATA[stack traceback:
	example_with_luaunit.lua:102: in function 'TestTiti.test1_withFailure']]></failure>
        </testcase>
        <testcase classname="TestTiti" name="TestTiti.test2_withFailure" time="0.000">
            <failure type="example_with_luaunit.lua:111: expected: &quot;bof&quot;
actual: &quot;hop&quot;">
                <![CDATA[stack traceback:
	example_with_luaunit.lua:111: in function 'TestTiti.test2_withFailure']]></failure>
        </testcase>
        <testcase classname="TestTiti" name="TestTiti.test3" time="0.000">
        </testcase>
        <testcase classname="TestToto" name="TestToto.test1_withFailure" time="0.000">
            <failure type="example_with_luaunit.lua:22: expected: 2, actual: 1">
                <![CDATA[stack traceback:
	example_with_luaunit.lua:22: in function 'TestToto.test1_withFailure']]></failure>
        </testcase>
        <testcase classname="TestToto" name="TestToto.test2_withFailure" time="0.000">
            <failure type="example_with_luaunit.lua:31: expected: &quot;bof&quot;
actual: &quot;hop&quot;">
                <![CDATA[stack traceback:
	example_with_luaunit.lua:31: in function 'TestToto.test2_withFailure']]></failure>
        </testcase>
        <testcase classname="TestToto" name="TestToto.test3" time="0.000">
        </testcase>
        <testcase classname="TestToto" name="TestToto.test4" time="0.000">
            <failure type="example_with_luaunit.lua:44: Received the not expected value: 1">
                <![CDATA[stack traceback:
	example_with_luaunit.lua:44: in function 'TestToto.test4']]></failure>
        </testcase>
        <testcase classname="TestToto" name="TestToto.test5" time="0.000">
            <failure type="example_with_luaunit.lua:50: expected: false, actual: 1">
                <![CDATA[stack traceback:
	example_with_luaunit.lua:50: in function 'TestToto.test5']]></failure>
        </testcase>
        <testcase classname="TestToto" name="TestToto.test6" time="0.000">
            <failure type="example_with_luaunit.lua:55: expected: true, actual: false">
                <![CDATA[stack traceback:
	example_with_luaunit.lua:55: in function 'TestToto.test6']]></failure>
        </testcase>
        <testcase classname="TestToto" name="TestToto.test7" time="0.000">
            <failure type="example_with_luaunit.lua:61: expected: {1, 2, three=3}
actual: {1, 2}">
                <![CDATA[stack traceback:
	example_with_luaunit.lua:61: in function 'TestToto.test7']]></failure>
        </testcase>
        <testcase classname="TestToto" name="TestToto.test8a" time="0.000">
            <error type="example_with_luaunit.lua:79: Bouhouhoum error!">
                <![CDATA[stack traceback:
	example_with_luaunit.lua:79: in function 'funcWithError'
	example_with_luaunit.lua:66: in function 'TestToto.test8a']]></error>
        </testcase>
        <testcase classname="TestToto" name="TestToto.test8b" time="0.000">
            <error type="example_with_luaunit.lua:79: Bouhouhoum error!">
                <![CDATA[stack traceback:
	example_with_luaunit.lua:79: in function 'funcWithError'
	example_with_luaunit.lua:75: in function 'funcWithFuncWithError'
	example_with_luaunit.lua:71: in function 'TestToto.test8b']]></error>
        </testcase>
        <testcase classname="[TestFunctions]" name="test1_withFailure" time="0.000">
            <error type="example_with_luaunit.lua:127: assertion failed!">
                <![CDATA[stack traceback:
	example_with_luaunit.lua:127: in function 'test1_withFailure']]></error>
        </testcase>
        <testcase classname="[TestFunctions]" name="test2_withFailure" time="0.000">
            <error type="example_with_luaunit.lua:133: assertion failed!">
                <![CDATA[stack traceback:
	example_with_luaunit.lua:133: in function 'test2_withFailure']]></error>
        </testcase>
        <testcase classname="[TestFunctions]" name="test3" time="0.000">
        </testcase>
    <system-out/>
    <system-err/>
    </testsuite>
</testsuites>
