FF.FF.FFFFEEEE.
Failed tests:
-------------
1) TestTiti.test1_withFailure
example_with_luaunit.lua:102: expected: 2, actual: 1
stack traceback:
	example_with_luaunit.lua:102: in function 'TestTiti.test1_withFailure'

2) TestTiti.test2_withFailure
example_with_luaunit.lua:111: expected: "bof"
actual: "hop"
stack traceback:
	example_with_luaunit.lua:111: in function 'TestTiti.test2_withFailure'

3) TestToto.test1_withFailure
example_with_luaunit.lua:22: expected: 2, actual: 1
stack traceback:
	example_with_luaunit.lua:22: in function 'TestToto.test1_withFailure'

4) TestToto.test2_withFailure
example_with_luaunit.lua:31: expected: "bof"
actual: "hop"
stack traceback:
	example_with_luaunit.lua:31: in function 'TestToto.test2_withFailure'

5) TestToto.test4
example_with_luaunit.lua:44: Received the not expected value: 1
stack traceback:
	example_with_luaunit.lua:44: in function 'TestToto.test4'

6) TestToto.test5
example_with_luaunit.lua:50: expected: false, actual: 1
stack traceback:
	example_with_luaunit.lua:50: in function 'TestToto.test5'

7) TestToto.test6
example_with_luaunit.lua:55: expected: true, actual: false
stack traceback:
	example_with_luaunit.lua:55: in function 'TestToto.test6'

8) TestToto.test7
example_with_luaunit.lua:61: expected: {1, 2, three=3}
actual: {1, 2}
stack traceback:
	example_with_luaunit.lua:61: in function 'TestToto.test7'

9) TestToto.test8a
example_with_luaunit.lua:79: Bouhouhoum error!
stack traceback:
	example_with_luaunit.lua:79: in function 'funcWithError'
	example_with_luaunit.lua:66: in function 'TestToto.test8a'

10) TestToto.test8b
example_with_luaunit.lua:79: Bouhouhoum error!
stack traceback:
	example_with_luaunit.lua:79: in function 'funcWithError'
	example_with_luaunit.lua:75: in function 'funcWithFuncWithError'
	example_with_luaunit.lua:71: in function 'TestToto.test8b'

11) test1_withFailure
example_with_luaunit.lua:127: assertion failed!
stack traceback:
	example_with_luaunit.lua:127: in function 'test1_withFailure'

12) test2_withFailure
example_with_luaunit.lua:133: assertion failed!
stack traceback:
	example_with_luaunit.lua:133: in function 'test2_withFailure'

Ran 15 tests in 0.012 seconds, 3 successes, 8 failures, 4 errors
