1..15
# Started on 01/30/16 22:19:36
# Starting class: TestTiti
not ok 1	TestTiti.test1_withFailure
    example_with_luaunit.lua:102: expected: 2, actual: 1
    stack traceback:
    	example_with_luaunit.lua:102: in function 'TestTiti.test1_withFailure'
not ok 2	TestTiti.test2_withFailure
    example_with_luaunit.lua:111: expected: "bof"
    actual: "hop"
    stack traceback:
    	example_with_luaunit.lua:111: in function 'TestTiti.test2_withFailure'
ok     3	TestTiti.test3
# Starting class: TestToto
not ok 4	TestToto.test1_withFailure
    example_with_luaunit.lua:22: expected: 2, actual: 1
    stack traceback:
    	example_with_luaunit.lua:22: in function 'TestToto.test1_withFailure'
not ok 5	TestToto.test2_withFailure
    example_with_luaunit.lua:31: expected: "bof"
    actual: "hop"
    stack traceback:
    	example_with_luaunit.lua:31: in function 'TestToto.test2_withFailure'
ok     6	TestToto.test3
not ok 7	TestToto.test4
    example_with_luaunit.lua:44: Received the not expected value: 1
    stack traceback:
    	example_with_luaunit.lua:44: in function 'TestToto.test4'
not ok 8	TestToto.test5
    example_with_luaunit.lua:50: expected: false, actual: 1
    stack traceback:
    	example_with_luaunit.lua:50: in function 'TestToto.test5'
not ok 9	TestToto.test6
    example_with_luaunit.lua:55: expected: true, actual: false
    stack traceback:
    	example_with_luaunit.lua:55: in function 'TestToto.test6'
not ok 10	TestToto.test7
    example_with_luaunit.lua:61: expected: {1, 2, three=3}
    actual: {1, 2}
    stack traceback:
    	example_with_luaunit.lua:61: in function 'TestToto.test7'
not ok 11	TestToto.test8a
    example_with_luaunit.lua:79: Bouhouhoum error!
    stack traceback:
    	example_with_luaunit.lua:79: in function 'funcWithError'
    	example_with_luaunit.lua:66: in function 'TestToto.test8a'
not ok 12	TestToto.test8b
    example_with_luaunit.lua:79: Bouhouhoum error!
    stack traceback:
    	example_with_luaunit.lua:79: in function 'funcWithError'
    	example_with_luaunit.lua:75: in function 'funcWithFuncWithError'
    	example_with_luaunit.lua:71: in function 'TestToto.test8b'
not ok 13	test1_withFailure
    example_with_luaunit.lua:127: assertion failed!
    stack traceback:
    	example_with_luaunit.lua:127: in function 'test1_withFailure'
not ok 14	test2_withFailure
    example_with_luaunit.lua:133: assertion failed!
    stack traceback:
    	example_with_luaunit.lua:133: in function 'test2_withFailure'
ok     15	test3
# Ran 15 tests in 0.000 seconds, 3 successes, 8 failures, 4 errors
